<?xml version="1.0" encoding="utf-8"?>
<!-- =================================================================================== -->
<!-- |    This document was autogenerated by xacro from urdf_xacro/example_track_gazebo.urdf.xacro | -->
<!-- |    EDITING THIS FILE BY HAND IS NOT RECOMMENDED                                 | -->
<!-- =================================================================================== -->
<robot name="double_tracks">


  <link name="my_base_link">
    <visual>
      <geometry>
        <box size="0.1 0.1 0.1 "/>
      </geometry>
    </visual>
    <collision>
      <geometry>
        <box size="0.1 0.1 0.1 "/>
      </geometry>
    </collision>
  </link>
  <joint name="left_body_joint" type="fixed">
    <origin rpy="0 0 0" xyz="0 -1 0"/>
    <parent link="my_base_link"/>
    <child link="left_body"/>
  </joint>
  <joint name="right_body_joint" type="fixed">
    <origin rpy="0 0 0" xyz="0 1 0"/>
    <parent link="my_base_link"/>
    <child link="right_body"/>
  </joint>

  <link name="left_body">
    <inertial>
      <mass value="1"/>
      <inertia ixx="0.0250083333333" ixy="0" ixz="0" iyy="0.0241666666667" iyz="0" izz="0.0425083333333"/>
    </inertial>
    <visual>
      <geometry>
        <box size="0.5 0.51 0.2"/>
      </geometry>
    </visual>
    <collision>
      <geometry>
        <box size="0.51 0.5 0.2"/>
      </geometry>
    </collision>
  </link>
  <!-- sprocket driving the track : cylinder -->
  <link name="left_sprocket">
    <inertial>
      <mass value="0.2"/>
      <!-- assuming axis of cylinder is y, not z -->
      <inertia ixx="0.004655" ixy="0" ixz="0" iyy="0.00064" iyz="0" izz="0.004655"/>
    </inertial>
    <visual>
      <origin rpy="1.57079632679 0 0" xyz="0 0 0"/>
      <geometry>
        <cylinder length="0.51" radius="0.08"/>
      </geometry>
    </visual>
    <visual>
      <geometry>
        <box size="0.01 0.51 0.20"/>
      </geometry>
    </visual>
    <visual>
      <geometry>
        <box size="0.20 0.51 0.01"/>
      </geometry>
    </visual>
    <collision>
      <origin rpy="1.57079632679 0 0" xyz="0 0 0"/>
      <geometry>
        <cylinder length="0.51" radius="0.08"/>
      </geometry>
    </collision>
  </link>
  <joint name="left_sprocket_axle" type="continuous">
    <origin rpy="0 0 0" xyz="0.35 -0.001 0"/>
    <parent link="left_body"/>
    <child link="left_sprocket"/>
    <axis xyz="0 1 0"/>
  </joint>
  <!-- <transmission name="left_sprocket_transmission">
    <type>transmission_interface/SimpleTransmission</type>
    <joint name="left_sprocket_axle">
      <hardwareInterface>hardware_interface/VelocityJointInterface</hardwareInterface>
    </joint>
    <actuator name="left_sprocket_actuator">
      <mechanicalReduction>1</mechanicalReduction>
    </actuator>
  </transmission> -->
    <transmission name="left_sprocket_transmission" type="SimpleTransmission">
			<type>transmission_interface/SimpleTransmission</type>
			<actuator name="left_sprocket_actuator">
				<mechanicalReduction>1</mechanicalReduction>
			</actuator>
			<joint name="left_sprocket_axle">
				<hardwareInterface>hardware_interface/VelocityJointInterface</hardwareInterface>
			</joint>
  </transmission>
  <!-- idler on the other side of the sprocket: cylinder -->
  <link name="left_idler">
    <inertial>
      <mass value="0.2"/>
      <!-- assuming axis of cylinder is y, not z -->
      <inertia ixx="0.004655" ixy="0" ixz="0" iyy="0.00064" iyz="0" izz="0.004655"/>
    </inertial>
    <visual>
      <origin rpy="1.57079632679 0 0" xyz="0 0 0"/>
      <geometry>
        <cylinder length="0.51" radius="0.08"/>
      </geometry>
    </visual>
    <collision>
      <origin rpy="1.57079632679 0 0" xyz="0 0 0"/>
      <geometry>
        <cylinder length="0.51" radius="0.08"/>
      </geometry>
    </collision>
  </link>
  <joint name="left_idler_axle" type="fixed">
    <origin rpy="0 0 0" xyz="-0.35 0 0"/>
    <parent link="left_body"/>
    <child link="left_idler"/>
  </joint>
  <!-- -->
  <gazebo>
    <link name="left_track_straight_segment_link0">
      <pose>-0.35 -1 0.115 0 0 0</pose>
      <inertial>
        <pose>0.35 0 -0.0575 0 0 0</pose>
        <mass>0.1</mass>
        <inertia>
          <ixx>0.00219354166667</ixx>
          <ixy>0</ixy>
          <ixz>0</ixz>
          <iyy>0.00419354166667</iyy>
          <iyz>0</iyz>
          <izz>0.00616666666667</izz>
        </inertia>
      </inertial>
      <collision name="left_collision">
        <pose>0.35 0 -0.0575 0 0 0</pose>
        <geometry>
          <box>
            <size>0.7 0.5 0.115</size>
          </box>
        </geometry>
        <surface>
          <friction>
            <ode>
              <mu>0.5</mu>
              <mu2>0.5</mu2>
            </ode>
          </friction>
          <contact>
            <ode>
              <min_depth>0.01</min_depth>
            </ode>
          </contact>
        </surface>
      </collision>
      <visual name="left_visual">
        <pose>0.35 0 -0.0575 0 0 0</pose>
        <geometry>
          <box>
            <size>0.7 0.5 0.115</size>
          </box>
        </geometry>
        <material>
          <ambient>0.1 0.1 0.3 1</ambient>
          <diffuse>0.2 0.2 0.2 1</diffuse>
          <specular>0 0 0 1</specular>
          <emissive>0 0 0 1</emissive>
        </material>
      </visual>
    </link>
  </gazebo>
  <gazebo>
    <link name="left_track_straight_segment_link1">
      <pose>0.35 -1 -0.115 0 3.14159265359 0</pose>
      <inertial>
        <pose>0.35 0 -0.0575 0 0 0</pose>
        <mass>0.1</mass>
        <inertia>
          <ixx>0.00219354166667</ixx>
          <ixy>0</ixy>
          <ixz>0</ixz>
          <iyy>0.00419354166667</iyy>
          <iyz>0</iyz>
          <izz>0.00616666666667</izz>
        </inertia>
      </inertial>
      <collision name="left_collision">
        <pose>0.35 0 -0.0575 0 0 0</pose>
        <geometry>
          <box>
            <size>0.7 0.5 0.115</size>
          </box>
        </geometry>
        <surface>
          <friction>
            <ode>
              <mu>0.5</mu>
              <mu2>0.5</mu2>
            </ode>
          </friction>
          <contact>
            <ode>
              <min_depth>0.01</min_depth>
            </ode>
          </contact>
        </surface>
      </collision>
      <visual name="left_visual">
        <pose>0.35 0 -0.0575 0 0 0</pose>
        <geometry>
          <box>
            <size>0.7 0.5 0.115</size>
          </box>
        </geometry>
        <material>
          <ambient>0.1 0.1 0.3 1</ambient>
          <diffuse>0.2 0.2 0.2 1</diffuse>
          <specular>0 0 0 1</specular>
          <emissive>0 0 0 1</emissive>
        </material>
      </visual>
    </link>
  </gazebo>
  <gazebo>
    <joint name="left_track_straight_segment_joint0" type="prismatic">
      <child>left_track_straight_segment_link0</child>
      <parent>left_body</parent>
      <axis>
        <xyz>1 0 0</xyz>
        <use_parent_model_frame>0</use_parent_model_frame>
      </axis>
      <physics>
        <ode>
          <implicit_spring_damper>1</implicit_spring_damper>
        </ode>
      </physics>
    </joint>
  </gazebo>
  <gazebo>
    <joint name="left_track_straight_segment_joint1" type="prismatic">
      <child>left_track_straight_segment_link1</child>
      <parent>left_body</parent>
      <axis>
        <xyz>1 0 0</xyz>
        <use_parent_model_frame>0</use_parent_model_frame>
      </axis>
      <physics>
        <ode>
          <implicit_spring_damper>1</implicit_spring_damper>
        </ode>
      </physics>
    </joint>
  </gazebo>
  <gazebo>
    <link name="left_track_arc_segment_link0">
      <pose>0.35 -1 0.115 0 0 0</pose>
      <inertial>
        <pose>0 0 -0.115 1.57079632679 0 0</pose>
        <mass>0.1</mass>
        <inertia>
          <ixx>0.00241395833333</ixx>
          <ixy>0</ixy>
          <ixz>0</ixz>
          <iyy>0.00241395833333</iyy>
          <iyz>0</iyz>
          <izz>0.00066125</izz>
        </inertia>
      </inertial>
      <collision name="left_collision">
        <pose>0 0 -0.115 1.57079632679 0 0</pose>
        <geometry>
          <cylinder>
            <length>0.5</length>
            <radius>0.115</radius>
          </cylinder>
        </geometry>
        <surface>
          <friction>
            <ode>
              <mu>0.5</mu>
              <mu2>0.5</mu2>
            </ode>
          </friction>
          <contact>
            <ode>
              <min_depth>0.01</min_depth>
            </ode>
          </contact>
        </surface>
      </collision>
      <visual name="left_visual">
        <pose>0 0 -0.115 1.57079632679 0 0</pose>
        <geometry>
          <cylinder>
            <length>0.5</length>
            <radius>0.115</radius>
          </cylinder>
        </geometry>
        <material>
          <ambient>0.1 0.1 0.3 1</ambient>
          <diffuse>0.2 0.2 0.2 1</diffuse>
          <specular>0 0 0 1</specular>
          <emissive>0 0 0 1</emissive>
        </material>
      </visual>
    </link>
  </gazebo>
  <gazebo>
    <link name="left_track_arc_segment_link1">
      <pose>-0.35 -1 -0.115 0 3.14159265359 0</pose>
      <inertial>
        <pose>0 0 -0.115 1.57079632679 0 0</pose>
        <mass>0.1</mass>
        <inertia>
          <ixx>0.00241395833333</ixx>
          <ixy>0</ixy>
          <ixz>0</ixz>
          <iyy>0.00241395833333</iyy>
          <iyz>0</iyz>
          <izz>0.00066125</izz>
        </inertia>
      </inertial>
      <collision name="left_collision">
        <pose>0 0 -0.115 1.57079632679 0 0</pose>
        <geometry>
          <cylinder>
            <length>0.5</length>
            <radius>0.115</radius>
          </cylinder>
        </geometry>
        <surface>
          <friction>
            <ode>
              <mu>0.5</mu>
              <mu2>0.5</mu2>
            </ode>
          </friction>
          <contact>
            <ode>
              <min_depth>0.01</min_depth>
            </ode>
          </contact>
        </surface>
      </collision>
      <visual name="left_visual">
        <pose>0 0 -0.115 1.57079632679 0 0</pose>
        <geometry>
          <cylinder>
            <length>0.5</length>
            <radius>0.115</radius>
          </cylinder>
        </geometry>
        <material>
          <ambient>0.1 0.1 0.3 1</ambient>
          <diffuse>0.2 0.2 0.2 1</diffuse>
          <specular>0 0 0 1</specular>
          <emissive>0 0 0 1</emissive>
        </material>
      </visual>
    </link>
  </gazebo>
  <gazebo>
    <joint name="left_track_arc_segment_joint0" type="revolute">
      <child>left_track_arc_segment_link0</child>
      <parent>left_body</parent>
      <pose>0 0 -0.115 0 0 0</pose>
      <axis>
        <xyz>0 1 0</xyz>
        <use_parent_model_frame>0</use_parent_model_frame>
      </axis>
      <physics>
        <ode>
          <implicit_spring_damper>1</implicit_spring_damper>
        </ode>
      </physics>
    </joint>
  </gazebo>
  <gazebo>
    <joint name="left_track_arc_segment_joint1" type="revolute">
      <child>left_track_arc_segment_link1</child>
      <parent>left_body</parent>
      <pose>0 0 -0.115 0 0 0</pose>
      <axis>
        <xyz>0 1 0</xyz>
        <use_parent_model_frame>0</use_parent_model_frame>
      </axis>
      <physics>
        <ode>
          <implicit_spring_damper>1</implicit_spring_damper>
        </ode>
      </physics>
    </joint>
  </gazebo>
  <gazebo>
    <plugin filename="libContinuousTrack.so" name="left_track">
      <sprocket>
        <joint>left_sprocket_axle</joint>
        <pitch_diameter>0.24</pitch_diameter>
      </sprocket>
      <trajectory>
        <segment>
          <joint>left_track_straight_segment_joint0</joint>
          <end_position>0.7</end_position>
        </segment>
        <segment>
          <joint>left_track_arc_segment_joint0</joint>
          <end_position>3.14159265359</end_position>
        </segment>
        <segment>
          <joint>left_track_straight_segment_joint1</joint>
          <end_position>0.7</end_position>
        </segment>
        <segment>
          <joint>left_track_arc_segment_joint1</joint>
          <end_position>3.14159265359</end_position>
        </segment>
      </trajectory>
      <pattern>
        <elements_per_round>40</elements_per_round>
        <element>
          <collision name="left_collision">
            <pose>0 0 0 0 0 0</pose>
            <geometry>
              <box>
                <size>0.02 0.5 0.02</size>
              </box>
            </geometry>
            <surface>
              <friction>
                <ode>
                  <mu>0.5</mu>
                  <mu2>0.5</mu2>
                </ode>
              </friction>
              <contact>
                <ode>
                  <min_depth>0.01</min_depth>
                </ode>
              </contact>
            </surface>
          </collision>
          <visual name="left_visual">
            <pose>0 0 0 0 0 0</pose>
            <geometry>
              <box>
                <size>0.02 0.5 0.02</size>
              </box>
            </geometry>
            <material>
              <ambient>0.1 0.1 0.3 1</ambient>
              <diffuse>0.2 0.2 0.2 1</diffuse>
              <specular>0 0 0 1</specular>
              <emissive>0 0 0 1</emissive>
            </material>
          </visual>
        </element>
        <element>
          <collision name="left_collision">
            <pose>0 0.25 0 1.57079632679 0 0</pose>
            <geometry>
              <polyline>
                <point>-0.02 -0.01</point>
                <point>-0.01 0.01</point>
                <point>0.01 0.01</point>
                <point>0.02 -0.01</point>
                <height>0.5</height>
              </polyline>
            </geometry>
            <surface>
              <friction>
                <ode>
                  <mu>0.5</mu>
                  <mu2>0.5</mu2>
                </ode>
              </friction>
              <contact>
                <ode>
                  <min_depth>0.01</min_depth>
                </ode>
              </contact>
            </surface>
          </collision>
          <visual name="left_visual">
            <pose>0 0.25 0 1.57079632679 0 0</pose>
            <geometry>
              <polyline>
                <point>-0.02 -0.01</point>
                <point>-0.01 0.01</point>
                <point>0.01 0.01</point>
                <point>0.02 -0.01</point>
                <height>0.5</height>
              </polyline>
            </geometry>
            <material>
              <ambient>0.1 0.1 0.3 1</ambient>
              <diffuse>0.2 0.2 0.2 1</diffuse>
              <specular>0 0 0 1</specular>
              <emissive>0 0 0 1</emissive>
            </material>
          </visual>
        </element>
      </pattern>
    </plugin>
  </gazebo>

  <link name="right_body">
    <inertial>
      <mass value="1"/>
      <inertia ixx="0.0250083333333" ixy="0" ixz="0" iyy="0.0241666666667" iyz="0" izz="0.0425083333333"/>
    </inertial>
    <visual>
      <geometry>
        <box size="0.5 0.51 0.2"/>
      </geometry>
    </visual>
    <collision>
      <geometry>
        <box size="0.51 0.5 0.2"/>
      </geometry>
    </collision>
  </link>
  <!-- sprocket driving the track : cylinder -->
  <link name="right_sprocket">
    <inertial>
      <mass value="0.2"/>
      <!-- assuming axis of cylinder is y, not z -->
      <inertia ixx="0.004655" ixy="0" ixz="0" iyy="0.00064" iyz="0" izz="0.004655"/>
    </inertial>
    <visual>
      <origin rpy="1.57079632679 0 0" xyz="0 0 0"/>
      <geometry>
        <cylinder length="0.51" radius="0.08"/>
      </geometry>
    </visual>
    <visual>
      <geometry>
        <box size="0.01 0.51 0.20"/>
      </geometry>
    </visual>
    <visual>
      <geometry>
        <box size="0.20 0.51 0.01"/>
      </geometry>
    </visual>
    <collision>
      <origin rpy="1.57079632679 0 0" xyz="0 0 0"/>
      <geometry>
        <cylinder length="0.51" radius="0.08"/>
      </geometry>
    </collision>
  </link>
  <joint name="right_sprocket_axle" type="continuous">
    <origin rpy="0 0 0" xyz="0.35 0.001 0"/>
    <parent link="right_body"/>
    <child link="right_sprocket"/>
    <axis xyz="0 1 0"/>
  </joint>
  <!-- <transmission name="right_sprocket_transmission">
    <type>transmission_interface/SimpleTransmission</type>
    <actuator name="right_sprocket_actuator">
      <mechanicalReduction>1</mechanicalReduction>
    </actuator>
    <joint name="right_sprocket_axle">
      <hardwareInterface>hardware_interface/VelocityJointInterface</hardwareInterface>
    </joint>
  </transmission> -->
  <transmission name="right_sprocket_transmission" type="SimpleTransmission">
    <type>transmission_interface/SimpleTransmission</type>
    <actuator name="right_sprocket_actuator">
        <mechanicalReduction>1</mechanicalReduction>
    </actuator>
    <joint name="right_sprocket_axle">
        <hardwareInterface>hardware_interface/VelocityJointInterface</hardwareInterface>
    </joint>
  </transmission>

  <!-- idler on the other side of the sprocket: cylinder -->
  <link name="right_idler">
    <inertial>
      <mass value="0.2"/>
      <!-- assuming axis of cylinder is y, not z -->
      <inertia ixx="0.004655" ixy="0" ixz="0" iyy="0.00064" iyz="0" izz="0.004655"/>
    </inertial>
    <visual>
      <origin rpy="1.57079632679 0 0" xyz="0 0 0"/>
      <geometry>
        <cylinder length="0.51" radius="0.08"/>
      </geometry>
    </visual>
    <collision>
      <origin rpy="1.57079632679 0 0" xyz="0 0 0"/>
      <geometry>
        <cylinder length="0.51" radius="0.08"/>
      </geometry>
    </collision>
  </link>
  <joint name="right_idler_axle" type="fixed">
    <origin rpy="0 0 0" xyz="-0.35 0 0"/>
    <parent link="right_body"/>
    <child link="right_idler"/>
  </joint>
  <!-- -->
  <gazebo>
    <link name="right_track_straight_segment_link0">
      <pose>-0.35 1 0.115 0 0 0</pose>
      <inertial>
        <pose>0.35 0 -0.0575 0 0 0</pose>
        <mass>0.1</mass>
        <inertia>
          <ixx>0.00219354166667</ixx>
          <ixy>0</ixy>
          <ixz>0</ixz>
          <iyy>0.00419354166667</iyy>
          <iyz>0</iyz>
          <izz>0.00616666666667</izz>
        </inertia>
      </inertial>
      <collision name="right_collision">
        <pose>0.35 0 -0.0575 0 0 0</pose>
        <geometry>
          <box>
            <size>0.7 0.5 0.115</size>
          </box>
        </geometry>
        <surface>
          <friction>
            <ode>
              <mu>0.5</mu>
              <mu2>0.5</mu2>
            </ode>
          </friction>
          <contact>
            <ode>
              <min_depth>0.01</min_depth>
            </ode>
          </contact>
        </surface>
      </collision>
      <visual name="right_visual">
        <pose>0.35 0 -0.0575 0 0 0</pose>
        <geometry>
          <box>
            <size>0.7 0.5 0.115</size>
          </box>
        </geometry>
        <material>
          <ambient>0.1 0.1 0.3 1</ambient>
          <diffuse>0.2 0.2 0.2 1</diffuse>
          <specular>0 0 0 1</specular>
          <emissive>0 0 0 1</emissive>
        </material>
      </visual>
    </link>
  </gazebo>
  <gazebo>
    <link name="right_track_straight_segment_link1">
      <pose>0.35 1 -0.115 0 3.14159265359 0</pose>
      <inertial>
        <pose>0.35 0 -0.0575 0 0 0</pose>
        <mass>0.1</mass>
        <inertia>
          <ixx>0.00219354166667</ixx>
          <ixy>0</ixy>
          <ixz>0</ixz>
          <iyy>0.00419354166667</iyy>
          <iyz>0</iyz>
          <izz>0.00616666666667</izz>
        </inertia>
      </inertial>
      <collision name="right_collision">
        <pose>0.35 0 -0.0575 0 0 0</pose>
        <geometry>
          <box>
            <size>0.7 0.5 0.115</size>
          </box>
        </geometry>
        <surface>
          <friction>
            <ode>
              <mu>0.5</mu>
              <mu2>0.5</mu2>
            </ode>
          </friction>
          <contact>
            <ode>
              <min_depth>0.01</min_depth>
            </ode>
          </contact>
        </surface>
      </collision>
      <visual name="right_visual">
        <pose>0.35 0 -0.0575 0 0 0</pose>
        <geometry>
          <box>
            <size>0.7 0.5 0.115</size>
          </box>
        </geometry>
        <material>
          <ambient>0.1 0.1 0.3 1</ambient>
          <diffuse>0.2 0.2 0.2 1</diffuse>
          <specular>0 0 0 1</specular>
          <emissive>0 0 0 1</emissive>
        </material>
      </visual>
    </link>
  </gazebo>
  <gazebo>
    <joint name="right_track_straight_segment_joint0" type="prismatic">
      <child>right_track_straight_segment_link0</child>
      <parent>right_body</parent>
      <axis>
        <xyz>1 0 0</xyz>
        <use_parent_model_frame>0</use_parent_model_frame>
      </axis>
      <physics>
        <ode>
          <implicit_spring_damper>1</implicit_spring_damper>
        </ode>
      </physics>
    </joint>
  </gazebo>
  <gazebo>
    <joint name="right_track_straight_segment_joint1" type="prismatic">
      <child>right_track_straight_segment_link1</child>
      <parent>right_body</parent>
      <axis>
        <xyz>1 0 0</xyz>
        <use_parent_model_frame>0</use_parent_model_frame>
      </axis>
      <physics>
        <ode>
          <implicit_spring_damper>1</implicit_spring_damper>
        </ode>
      </physics>
    </joint>
  </gazebo>
  <gazebo>
    <link name="right_track_arc_segment_link0">
      <pose>0.35 1 0.115 0 0 0</pose>
      <inertial>
        <pose>0 0 -0.115 1.57079632679 0 0</pose>
        <mass>0.1</mass>
        <inertia>
          <ixx>0.00241395833333</ixx>
          <ixy>0</ixy>
          <ixz>0</ixz>
          <iyy>0.00241395833333</iyy>
          <iyz>0</iyz>
          <izz>0.00066125</izz>
        </inertia>
      </inertial>
      <collision name="right_collision">
        <pose>0 0 -0.115 1.57079632679 0 0</pose>
        <geometry>
          <cylinder>
            <length>0.5</length>
            <radius>0.115</radius>
          </cylinder>
        </geometry>
        <surface>
          <friction>
            <ode>
              <mu>0.5</mu>
              <mu2>0.5</mu2>
            </ode>
          </friction>
          <contact>
            <ode>
              <min_depth>0.01</min_depth>
            </ode>
          </contact>
        </surface>
      </collision>
      <visual name="right_visual">
        <pose>0 0 -0.115 1.57079632679 0 0</pose>
        <geometry>
          <cylinder>
            <length>0.5</length>
            <radius>0.115</radius>
          </cylinder>
        </geometry>
        <material>
          <ambient>0.1 0.1 0.3 1</ambient>
          <diffuse>0.2 0.2 0.2 1</diffuse>
          <specular>0 0 0 1</specular>
          <emissive>0 0 0 1</emissive>
        </material>
      </visual>
    </link>
  </gazebo>
  <gazebo>
    <link name="right_track_arc_segment_link1">
      <pose>-0.35 1 -0.115 0 3.14159265359 0</pose>
      <inertial>
        <pose>0 0 -0.115 1.57079632679 0 0</pose>
        <mass>0.1</mass>
        <inertia>
          <ixx>0.00241395833333</ixx>
          <ixy>0</ixy>
          <ixz>0</ixz>
          <iyy>0.00241395833333</iyy>
          <iyz>0</iyz>
          <izz>0.00066125</izz>
        </inertia>
      </inertial>
      <collision name="right_collision">
        <pose>0 0 -0.115 1.57079632679 0 0</pose>
        <geometry>
          <cylinder>
            <length>0.5</length>
            <radius>0.115</radius>
          </cylinder>
        </geometry>
        <surface>
          <friction>
            <ode>
              <mu>0.5</mu>
              <mu2>0.5</mu2>
            </ode>
          </friction>
          <contact>
            <ode>
              <min_depth>0.01</min_depth>
            </ode>
          </contact>
        </surface>
      </collision>
      <visual name="right_visual">
        <pose>0 0 -0.115 1.57079632679 0 0</pose>
        <geometry>
          <cylinder>
            <length>0.5</length>
            <radius>0.115</radius>
          </cylinder>
        </geometry>
        <material>
          <ambient>0.1 0.1 0.3 1</ambient>
          <diffuse>0.2 0.2 0.2 1</diffuse>
          <specular>0 0 0 1</specular>
          <emissive>0 0 0 1</emissive>
        </material>
      </visual>
    </link>
  </gazebo>
  <gazebo>
    <joint name="right_track_arc_segment_joint0" type="revolute">
      <child>right_track_arc_segment_link0</child>
      <parent>right_body</parent>
      <pose>0 0 -0.115 0 0 0</pose>
      <axis>
        <xyz>0 1 0</xyz>
        <use_parent_model_frame>0</use_parent_model_frame>
      </axis>
      <physics>
        <ode>
          <implicit_spring_damper>1</implicit_spring_damper>
        </ode>
      </physics>
    </joint>
  </gazebo>
  <gazebo>
    <joint name="right_track_arc_segment_joint1" type="revolute">
      <child>right_track_arc_segment_link1</child>
      <parent>right_body</parent>
      <pose>0 0 -0.115 0 0 0</pose>
      <axis>
        <xyz>0 1 0</xyz>
        <use_parent_model_frame>0</use_parent_model_frame>
      </axis>
      <physics>
        <ode>
          <implicit_spring_damper>1</implicit_spring_damper>
        </ode>
      </physics>
    </joint>
  </gazebo>
  <gazebo>
    <plugin filename="libContinuousTrack.so" name="right_track">
      <sprocket>
        <joint>right_sprocket_axle</joint>
        <pitch_diameter>0.24</pitch_diameter>
      </sprocket>
      <trajectory>
        <segment>
          <joint>right_track_straight_segment_joint0</joint>
          <end_position>0.7</end_position>
        </segment>
        <segment>
          <joint>right_track_arc_segment_joint0</joint>
          <end_position>3.14159265359</end_position>
        </segment>
        <segment>
          <joint>right_track_straight_segment_joint1</joint>
          <end_position>0.7</end_position>
        </segment>
        <segment>
          <joint>right_track_arc_segment_joint1</joint>
          <end_position>3.14159265359</end_position>
        </segment>
      </trajectory>
      <pattern>
        <elements_per_round>40</elements_per_round>
        <element>
          <collision name="right_collision">
            <pose>0 0 0 0 0 0</pose>
            <geometry>
              <box>
                <size>0.02 0.5 0.02</size>
              </box>
            </geometry>
            <surface>
              <friction>
                <ode>
                  <mu>0.5</mu>
                  <mu2>0.5</mu2>
                </ode>
              </friction>
              <contact>
                <ode>
                  <min_depth>0.01</min_depth>
                </ode>
              </contact>
            </surface>
          </collision>
          <visual name="right_visual">
            <pose>0 0 0 0 0 0</pose>
            <geometry>
              <box>
                <size>0.02 0.5 0.02</size>
              </box>
            </geometry>
            <material>
              <ambient>0.1 0.1 0.3 1</ambient>
              <diffuse>0.2 0.2 0.2 1</diffuse>
              <specular>0 0 0 1</specular>
              <emissive>0 0 0 1</emissive>
            </material>
          </visual>
        </element>
        <element>
          <collision name="right_collision">
            <pose>0 0.25 0 1.57079632679 0 0</pose>
            <geometry>
              <polyline>
                <point>-0.02 -0.01</point>
                <point>-0.01 0.01</point>
                <point>0.01 0.01</point>
                <point>0.02 -0.01</point>
                <height>0.5</height>
              </polyline>
            </geometry>
            <surface>
              <friction>
                <ode>
                  <mu>0.5</mu>
                  <mu2>0.5</mu2>
                </ode>
              </friction>
              <contact>
                <ode>
                  <min_depth>0.01</min_depth>
                </ode>
              </contact>
            </surface>
          </collision>
          <visual name="right_visual">
            <pose>0 0.25 0 1.57079632679 0 0</pose>
            <geometry>
              <polyline>
                <point>-0.02 -0.01</point>
                <point>-0.01 0.01</point>
                <point>0.01 0.01</point>
                <point>0.02 -0.01</point>
                <height>0.5</height>
              </polyline>
            </geometry>
            <material>
              <ambient>0.1 0.1 0.3 1</ambient>
              <diffuse>0.2 0.2 0.2 1</diffuse>
              <specular>0 0 0 1</specular>
              <emissive>0 0 0 1</emissive>
            </material>
          </visual>
        </element>
      </pattern>
    </plugin>
  </gazebo>

  <!-- ros_control for gazebo -->
  <gazebo>
    <plugin filename="libgazebo_ros_control.so" name="gazebo_ros_control">
      <robotSimType>gazebo_ros_control/DefaultRobotHWSim</robotSimType>
      <legacyModeNS>true</legacyModeNS>
    </plugin>
  </gazebo>
  
</robot>
