<?xml version="1.0" encoding="utf-8"?>
<!-- =================================================================================== -->
<!-- |    This document was autogenerated by xacro from urdf_xacro/example_track_simple_gazebo.urdf.xacro | -->
<!-- |    EDITING THIS FILE BY HAND IS NOT RECOMMENDED                                 | -->
<!-- =================================================================================== -->
<robot name="example_track_simple">
  <!-- -->
  <!--                                                                                              -->
  <!-- macros for making simple track                                                               -->
  <!--     * useful when difining entities for ContinuousTrackSimple plugin                         -->
  <!--     * see gazebo_continuous_track_example/urdf/example_track_simple.urdf.xacro to know usage -->
  <!--                                                                                              -->
  <!-- macros which expand to inertial/collision/visual -->
  <!-- macros which expand to box/polyline collision and visual. convenient when defining pattern elements on a track -->
  <!-- macros for populating general links/joints -->
  <!-- track segment templates which can be used with above population macros -->
  <!-- macros for populating track segments with above population macros and above templates -->
  <!-- macro which expands to simple plugin definition -->
  <!-- main entry point: macro for making oval track by ContinuousTrackSimple plugin -->
  <!-- URDF file for general ROS systems such as ros_control, rviz, etc.           -->
  <!-- We define here;                                                             -->
  <!--     * a body to be wrapped by the track                                     -->
  <!--     * a sprocket to drive the track                                         -->
  <!--     * an axle and actuator for the sprocket                                 -->
  <!--     * an idler wheel on the other side of the sprocket                      -->
  <!-- Other entities specialized for Gazebo are defined in *_gazebo.urdf.xacro .  -->
  <!-- body to be wrapped by the track: box -->
  <link name="body">
    <inertial>
      <mass value="1"/>
      <inertia ixx="0.0250083333333" ixy="0" ixz="0" iyy="0.0241666666667" iyz="0" izz="0.0425083333333"/>
    </inertial>
    <visual>
      <geometry>
        <box size="0.5 0.51 0.2"/>
      </geometry>
    </visual>
    <collision>
      <geometry>
        <box size="0.51 0.5 0.2"/>
      </geometry>
    </collision>
  </link>
  <!-- sprocket driving the track : cylinder -->
  <link name="sprocket">
    <inertial>
      <mass value="0.2"/>
      <!-- assuming axis of cylinder is y, not z -->
      <inertia ixx="0.004655" ixy="0" ixz="0" iyy="0.00064" iyz="0" izz="0.004655"/>
    </inertial>
    <visual>
      <origin rpy="1.57079632679 0 0" xyz="0 0 0"/>
      <geometry>
        <cylinder length="0.51" radius="0.08"/>
      </geometry>
    </visual>
    <visual>
      <geometry>
        <box size="0.01 0.51 0.20"/>
      </geometry>
    </visual>
    <visual>
      <geometry>
        <box size="0.20 0.51 0.01"/>
      </geometry>
    </visual>
    <collision>
      <origin rpy="1.57079632679 0 0" xyz="0 0 0"/>
      <geometry>
        <cylinder length="0.51" radius="0.08"/>
      </geometry>
    </collision>
  </link>
  <joint name="sprocket_axle" type="continuous">
    <origin rpy="0 0 0" xyz="0.35 0 0"/>
    <parent link="body"/>
    <child link="sprocket"/>
    <axis xyz="0 1 0"/>
  </joint>
  <transmission name="sprocket_transmission">
    <type>transmission_interface/SimpleTransmission</type>
    <joint name="sprocket_axle">
      <hardwareInterface>hardware_interface/VelocityJointInterface</hardwareInterface>
    </joint>
    <actuator name="sprocket_actuator">
      <mechanicalReduction>1</mechanicalReduction>
    </actuator>
  </transmission>
  <!-- idler on the other side of the sprocket: cylinder -->
  <link name="idler">
    <inertial>
      <mass value="0.2"/>
      <!-- assuming axis of cylinder is y, not z -->
      <inertia ixx="0.004655" ixy="0" ixz="0" iyy="0.00064" iyz="0" izz="0.004655"/>
    </inertial>
    <visual>
      <origin rpy="1.57079632679 0 0" xyz="0 0 0"/>
      <geometry>
        <cylinder length="0.51" radius="0.08"/>
      </geometry>
    </visual>
    <collision>
      <origin rpy="1.57079632679 0 0" xyz="0 0 0"/>
      <geometry>
        <cylinder length="0.51" radius="0.08"/>
      </geometry>
    </collision>
  </link>
  <joint name="idler_axle" type="fixed">
    <origin rpy="0 0 0" xyz="-0.35 0 0"/>
    <parent link="body"/>
    <child link="idler"/>
  </joint>
  <!-- -->
  <gazebo>
    <link name="track_straight_segment_link0">
      <pose>-0.35 0 0.125 0 0 0</pose>
      <inertial>
        <pose>0.35 0 -0.0625 0 0 0</pose>
        <mass>0.1</mass>
        <inertia>
          <ixx>0.00221354166667</ixx>
          <ixy>0</ixy>
          <ixz>0</ixz>
          <iyy>0.00421354166667</iyy>
          <iyz>0</iyz>
          <izz>0.00616666666667</izz>
        </inertia>
      </inertial>
      <collision name="collision">
        <pose>0.35 0 -0.0625 0 0 0</pose>
        <geometry>
          <box>
            <size>0.7 0.5 0.125</size>
          </box>
        </geometry>
        <surface>
          <friction>
            <ode>
              <mu>0.5</mu>
              <mu2>0.5</mu2>
            </ode>
          </friction>
          <contact>
            <ode>
              <min_depth>0.01</min_depth>
            </ode>
          </contact>
        </surface>
      </collision>
      <visual name="visual">
        <pose>0.35 0 -0.0625 0 0 0</pose>
        <geometry>
          <box>
            <size>0.7 0.5 0.125</size>
          </box>
        </geometry>
        <material>
          <ambient>0.1 0.3 0.1 1</ambient>
          <diffuse>0.2 0.2 0.2 1</diffuse>
          <specular>0 0 0 1</specular>
          <emissive>0 0 0 1</emissive>
        </material>
      </visual>
    </link>
  </gazebo>
  <gazebo>
    <link name="track_straight_segment_link1">
      <pose>0.35 0 -0.125 0 3.14159265359 0</pose>
      <inertial>
        <pose>0.35 0 -0.0625 0 0 0</pose>
        <mass>0.1</mass>
        <inertia>
          <ixx>0.00221354166667</ixx>
          <ixy>0</ixy>
          <ixz>0</ixz>
          <iyy>0.00421354166667</iyy>
          <iyz>0</iyz>
          <izz>0.00616666666667</izz>
        </inertia>
      </inertial>
      <collision name="collision">
        <pose>0.35 0 -0.0625 0 0 0</pose>
        <geometry>
          <box>
            <size>0.7 0.5 0.125</size>
          </box>
        </geometry>
        <surface>
          <friction>
            <ode>
              <mu>0.5</mu>
              <mu2>0.5</mu2>
            </ode>
          </friction>
          <contact>
            <ode>
              <min_depth>0.01</min_depth>
            </ode>
          </contact>
        </surface>
      </collision>
      <visual name="visual">
        <pose>0.35 0 -0.0625 0 0 0</pose>
        <geometry>
          <box>
            <size>0.7 0.5 0.125</size>
          </box>
        </geometry>
        <material>
          <ambient>0.1 0.3 0.1 1</ambient>
          <diffuse>0.2 0.2 0.2 1</diffuse>
          <specular>0 0 0 1</specular>
          <emissive>0 0 0 1</emissive>
        </material>
      </visual>
    </link>
  </gazebo>
  <gazebo>
    <joint name="track_straight_segment_joint0" type="prismatic">
      <child>track_straight_segment_link0</child>
      <parent>body</parent>
      <axis>
        <xyz>1 0 0</xyz>
        <use_parent_model_frame>0</use_parent_model_frame>
      </axis>
      <physics>
        <ode>
          <implicit_spring_damper>1</implicit_spring_damper>
        </ode>
      </physics>
    </joint>
  </gazebo>
  <gazebo>
    <joint name="track_straight_segment_joint1" type="prismatic">
      <child>track_straight_segment_link1</child>
      <parent>body</parent>
      <axis>
        <xyz>1 0 0</xyz>
        <use_parent_model_frame>0</use_parent_model_frame>
      </axis>
      <physics>
        <ode>
          <implicit_spring_damper>1</implicit_spring_damper>
        </ode>
      </physics>
    </joint>
  </gazebo>
  <gazebo>
    <link name="track_arc_segment_link0">
      <pose>0.35 0 0.125 0 0 0</pose>
      <inertial>
        <pose>0 0 -0.125 1.57079632679 0 0</pose>
        <mass>0.1</mass>
        <inertia>
          <ixx>0.00247395833333</ixx>
          <ixy>0</ixy>
          <ixz>0</ixz>
          <iyy>0.00247395833333</iyy>
          <iyz>0</iyz>
          <izz>0.00078125</izz>
        </inertia>
      </inertial>
      <collision name="collision">
        <pose>0 0 -0.125 1.57079632679 0 0</pose>
        <geometry>
          <cylinder>
            <length>0.5</length>
            <radius>0.125</radius>
          </cylinder>
        </geometry>
        <surface>
          <friction>
            <ode>
              <mu>0.5</mu>
              <mu2>0.5</mu2>
            </ode>
          </friction>
          <contact>
            <ode>
              <min_depth>0.01</min_depth>
            </ode>
          </contact>
        </surface>
      </collision>
      <visual name="visual">
        <pose>0 0 -0.125 1.57079632679 0 0</pose>
        <geometry>
          <cylinder>
            <length>0.5</length>
            <radius>0.125</radius>
          </cylinder>
        </geometry>
        <material>
          <ambient>0.1 0.3 0.1 1</ambient>
          <diffuse>0.2 0.2 0.2 1</diffuse>
          <specular>0 0 0 1</specular>
          <emissive>0 0 0 1</emissive>
        </material>
      </visual>
    </link>
  </gazebo>
  <gazebo>
    <link name="track_arc_segment_link1">
      <pose>-0.35 0 -0.125 0 3.14159265359 0</pose>
      <inertial>
        <pose>0 0 -0.125 1.57079632679 0 0</pose>
        <mass>0.1</mass>
        <inertia>
          <ixx>0.00247395833333</ixx>
          <ixy>0</ixy>
          <ixz>0</ixz>
          <iyy>0.00247395833333</iyy>
          <iyz>0</iyz>
          <izz>0.00078125</izz>
        </inertia>
      </inertial>
      <collision name="collision">
        <pose>0 0 -0.125 1.57079632679 0 0</pose>
        <geometry>
          <cylinder>
            <length>0.5</length>
            <radius>0.125</radius>
          </cylinder>
        </geometry>
        <surface>
          <friction>
            <ode>
              <mu>0.5</mu>
              <mu2>0.5</mu2>
            </ode>
          </friction>
          <contact>
            <ode>
              <min_depth>0.01</min_depth>
            </ode>
          </contact>
        </surface>
      </collision>
      <visual name="visual">
        <pose>0 0 -0.125 1.57079632679 0 0</pose>
        <geometry>
          <cylinder>
            <length>0.5</length>
            <radius>0.125</radius>
          </cylinder>
        </geometry>
        <material>
          <ambient>0.1 0.3 0.1 1</ambient>
          <diffuse>0.2 0.2 0.2 1</diffuse>
          <specular>0 0 0 1</specular>
          <emissive>0 0 0 1</emissive>
        </material>
      </visual>
    </link>
  </gazebo>
  <gazebo>
    <joint name="track_arc_segment_joint0" type="revolute">
      <child>track_arc_segment_link0</child>
      <parent>body</parent>
      <pose>0 0 -0.125 0 0 0</pose>
      <axis>
        <xyz>0 1 0</xyz>
        <use_parent_model_frame>0</use_parent_model_frame>
      </axis>
      <physics>
        <ode>
          <implicit_spring_damper>1</implicit_spring_damper>
        </ode>
      </physics>
    </joint>
  </gazebo>
  <gazebo>
    <joint name="track_arc_segment_joint1" type="revolute">
      <child>track_arc_segment_link1</child>
      <parent>body</parent>
      <pose>0 0 -0.125 0 0 0</pose>
      <axis>
        <xyz>0 1 0</xyz>
        <use_parent_model_frame>0</use_parent_model_frame>
      </axis>
      <physics>
        <ode>
          <implicit_spring_damper>1</implicit_spring_damper>
        </ode>
      </physics>
    </joint>
  </gazebo>
  <gazebo>
    <plugin filename="libContinuousTrackSimple.so" name="track">
      <sprocket>
        <joint>sprocket_axle</joint>
        <pitch_diameter>0.24</pitch_diameter>
      </sprocket>
      <track>
        <segment>
          <joint>track_straight_segment_joint0</joint>
        </segment>
        <segment>
          <joint>track_arc_segment_joint0</joint>
          <pitch_diameter>0.24</pitch_diameter>
        </segment>
        <segment>
          <joint>track_straight_segment_joint1</joint>
        </segment>
        <segment>
          <joint>track_arc_segment_joint1</joint>
          <pitch_diameter>0.24</pitch_diameter>
        </segment>
      </track>
    </plugin>
  </gazebo>
  <!-- ros_control for gazebo -->
  <gazebo>
    <plugin filename="libgazebo_ros_control.so" name="gazebo_ros_control">
      <robotSimType>gazebo_ros_control/DefaultRobotHWSim</robotSimType>
      <legacyModeNS>false</legacyModeNS>
    </plugin>
  </gazebo>
</robot>
