<?xml version="1.0" encoding="utf-8"?>
<!-- =================================================================================== -->
<!-- |    This document was autogenerated by xacro from urdf_xacro/example_lugged_wheel_gazebo.urdf.xacro | -->
<!-- |    EDITING THIS FILE BY HAND IS NOT RECOMMENDED                                 | -->
<!-- =================================================================================== -->
<robot name="example_lugged_wheel">
  <!-- -->
  <!--                                -->
  <!-- macros for making lugged wheel -->
  <!--                                -->
  <!-- macros which expand to inertial/collision/visual -->
  <!-- macros which expand to box/polyline collision and visual. convenient when defining pattern elements on a track -->
  <!-- macros for populating general links/joints -->
  <!-- track segment templates which can be used with above population macros -->
  <!-- macros for populating track segments with above population macros and above templates -->
  <!-- macro which expands to plugin definition -->
  <!-- main entry point: macro for making a lugged wheel by ContinuousTrack plugin -->
  <!-- URDF file for general ROS systems such as ros_control, rviz, etc.           -->
  <!-- We define here;                                                             -->
  <!--     * a stabilizer plate as a parent body of wheels                         -->
  <!--     * a shaft to drive the wheels                                           -->
  <!--     * an axle and actuator for the sprocket                                 -->
  <!-- Other entities specialized for Gazebo are defined in *_gazebo.urdf.xacro .  -->
  <!-- stabilizer plate -->
  <link name="stabilizer">
    <inertial>
      <mass value="0.1"/>
      <inertia ixx="8.41666666667e-05" ixy="0" ixz="0" iyy="0.00208416666667" iyz="0" izz="0.00216666666667"/>
    </inertial>
    <visual>
      <geometry>
        <box size="0.5 0.1 0.01"/>
      </geometry>
    </visual>
    <collision>
      <geometry>
        <box size="0.5 0.1 0.01"/>
      </geometry>
    </collision>
  </link>
  <!-- shaft driving the wheels -->
  <link name="shaft">
    <inertial>
      <mass value="0.05"/>
      <!-- assuming axis of cylinder is y, not z -->
      <inertia ixx="4.19791666667e-05" ixy="0" ixz="0" iyy="6.25e-07" iyz="0" izz="4.19791666667e-05"/>
    </inertial>
    <visual>
      <origin rpy="1.57079632679 0 0" xyz="0 0 0"/>
      <geometry>
        <cylinder length="0.1" radius="0.005"/>
      </geometry>
    </visual>
    <collision>
      <origin rpy="1.57079632679 0 0" xyz="0 0 0"/>
      <geometry>
        <cylinder length="0.1" radius="0.005"/>
      </geometry>
    </collision>
  </link>
  <joint name="shaft_axle" type="continuous">
    <origin rpy="0 0 0" xyz="0.25 0 0"/>
    <parent link="stabilizer"/>
    <child link="shaft"/>
    <axis xyz="0 1 0"/>
  </joint>
  <transmission name="shaft_transmission">
    <type>transmission_interface/SimpleTransmission</type>
    <joint name="shaft_axle">
      <hardwareInterface>hardware_interface/VelocityJointInterface</hardwareInterface>
    </joint>
    <actuator name="shaft_actuator">
      <mechanicalReduction>1</mechanicalReduction>
    </actuator>
  </transmission>
  <!-- -->
  <gazebo>
    <link name="left_wheel_arc_segment_link0">
      <pose>0.25 0.15 0.115 0 0 0</pose>
      <inertial>
        <pose>0 0 -0.115 1.57079632679 0 0</pose>
        <mass>0.1</mass>
        <inertia>
          <ixx>0.000663958333333</ixx>
          <ixy>0</ixy>
          <ixz>0</ixz>
          <iyy>0.000663958333333</iyy>
          <iyz>0</iyz>
          <izz>0.00066125</izz>
        </inertia>
      </inertial>
      <collision name="collision">
        <pose>0 0 -0.115 1.57079632679 0 0</pose>
        <geometry>
          <cylinder>
            <length>0.2</length>
            <radius>0.115</radius>
          </cylinder>
        </geometry>
        <surface>
          <friction>
            <ode>
              <mu>0.5</mu>
              <mu2>0.5</mu2>
            </ode>
          </friction>
          <contact>
            <ode>
              <min_depth>0.01</min_depth>
            </ode>
          </contact>
        </surface>
      </collision>
      <visual name="visual">
        <pose>0 0 -0.115 1.57079632679 0 0</pose>
        <geometry>
          <cylinder>
            <length>0.2</length>
            <radius>0.115</radius>
          </cylinder>
        </geometry>
        <material>
          <ambient>0.8 0.8 0.8 1</ambient>
          <diffuse>0.2 0.2 0.2 1</diffuse>
          <specular>0 0 0 1</specular>
          <emissive>0 0 0 1</emissive>
        </material>
      </visual>
    </link>
  </gazebo>
  <gazebo>
    <joint name="left_wheel_arc_segment_joint0" type="revolute">
      <child>left_wheel_arc_segment_link0</child>
      <parent>stabilizer</parent>
      <pose>0 0 -0.115 0 0 0</pose>
      <axis>
        <xyz>0 1 0</xyz>
        <use_parent_model_frame>0</use_parent_model_frame>
      </axis>
      <physics>
        <ode>
          <implicit_spring_damper>1</implicit_spring_damper>
        </ode>
      </physics>
    </joint>
  </gazebo>
  <gazebo>
    <plugin filename="libContinuousTrack.so" name="left_wheel">
      <sprocket>
        <joint>shaft_axle</joint>
        <pitch_diameter>0.24</pitch_diameter>
      </sprocket>
      <trajectory>
        <segment>
          <joint>left_wheel_arc_segment_joint0</joint>
          <end_position>6.28318530718</end_position>
        </segment>
      </trajectory>
      <pattern>
        <elements_per_round>8</elements_per_round>
        <element>
          <collision name="collision">
            <pose>0 0 0.03 0 0 0</pose>
            <geometry>
              <box>
                <size>0.005 0.2 0.07</size>
              </box>
            </geometry>
            <surface>
              <friction>
                <ode>
                  <mu>0.5</mu>
                  <mu2>0.5</mu2>
                </ode>
              </friction>
              <contact>
                <ode>
                  <min_depth>0.01</min_depth>
                </ode>
              </contact>
            </surface>
          </collision>
          <visual name="visual">
            <pose>0 0 0.03 0 0 0</pose>
            <geometry>
              <box>
                <size>0.005 0.2 0.07</size>
              </box>
            </geometry>
            <material>
              <ambient>0.8 0.8 0.8 1</ambient>
              <diffuse>0.2 0.2 0.2 1</diffuse>
              <specular>0 0 0 1</specular>
              <emissive>0 0 0 1</emissive>
            </material>
          </visual>
        </element>
      </pattern>
    </plugin>
  </gazebo>
  <gazebo>
    <link name="right_wheel_arc_segment_link0">
      <pose>0.25 -0.15 0.115 0 0 0</pose>
      <inertial>
        <pose>0 0 -0.115 1.57079632679 0 0</pose>
        <mass>0.1</mass>
        <inertia>
          <ixx>0.000663958333333</ixx>
          <ixy>0</ixy>
          <ixz>0</ixz>
          <iyy>0.000663958333333</iyy>
          <iyz>0</iyz>
          <izz>0.00066125</izz>
        </inertia>
      </inertial>
      <collision name="collision">
        <pose>0 0 -0.115 1.57079632679 0 0</pose>
        <geometry>
          <cylinder>
            <length>0.2</length>
            <radius>0.115</radius>
          </cylinder>
        </geometry>
        <surface>
          <friction>
            <ode>
              <mu>0.5</mu>
              <mu2>0.5</mu2>
            </ode>
          </friction>
          <contact>
            <ode>
              <min_depth>0.01</min_depth>
            </ode>
          </contact>
        </surface>
      </collision>
      <visual name="visual">
        <pose>0 0 -0.115 1.57079632679 0 0</pose>
        <geometry>
          <cylinder>
            <length>0.2</length>
            <radius>0.115</radius>
          </cylinder>
        </geometry>
        <material>
          <ambient>0.8 0.8 0.8 1</ambient>
          <diffuse>0.2 0.2 0.2 1</diffuse>
          <specular>0 0 0 1</specular>
          <emissive>0 0 0 1</emissive>
        </material>
      </visual>
    </link>
  </gazebo>
  <gazebo>
    <joint name="right_wheel_arc_segment_joint0" type="revolute">
      <child>right_wheel_arc_segment_link0</child>
      <parent>stabilizer</parent>
      <pose>0 0 -0.115 0 0 0</pose>
      <axis>
        <xyz>0 1 0</xyz>
        <use_parent_model_frame>0</use_parent_model_frame>
      </axis>
      <physics>
        <ode>
          <implicit_spring_damper>1</implicit_spring_damper>
        </ode>
      </physics>
    </joint>
  </gazebo>
  <gazebo>
    <plugin filename="libContinuousTrack.so" name="right_wheel">
      <sprocket>
        <joint>shaft_axle</joint>
        <pitch_diameter>0.24</pitch_diameter>
      </sprocket>
      <trajectory>
        <segment>
          <joint>right_wheel_arc_segment_joint0</joint>
          <end_position>6.28318530718</end_position>
        </segment>
      </trajectory>
      <pattern>
        <elements_per_round>8</elements_per_round>
        <element>
          <collision name="collision">
            <pose>0 0 0.03 0 0 0</pose>
            <geometry>
              <box>
                <size>0.005 0.2 0.07</size>
              </box>
            </geometry>
            <surface>
              <friction>
                <ode>
                  <mu>0.5</mu>
                  <mu2>0.5</mu2>
                </ode>
              </friction>
              <contact>
                <ode>
                  <min_depth>0.01</min_depth>
                </ode>
              </contact>
            </surface>
          </collision>
          <visual name="visual">
            <pose>0 0 0.03 0 0 0</pose>
            <geometry>
              <box>
                <size>0.005 0.2 0.07</size>
              </box>
            </geometry>
            <material>
              <ambient>0.8 0.8 0.8 1</ambient>
              <diffuse>0.2 0.2 0.2 1</diffuse>
              <specular>0 0 0 1</specular>
              <emissive>0 0 0 1</emissive>
            </material>
          </visual>
        </element>
      </pattern>
    </plugin>
  </gazebo>
  <!-- low friction between the stabilizer and ground -->
  <gazebo reference="stabilizer">
    <mu1>0.01</mu1>
    <mu2>0.01</mu2>
  </gazebo>
  <!-- ros_control for gazebo -->
  <gazebo>
    <plugin filename="libgazebo_ros_control.so" name="gazebo_ros_control">
      <robotSimType>gazebo_ros_control/DefaultRobotHWSim</robotSimType>
      <legacyModeNS>false</legacyModeNS>
    </plugin>
  </gazebo>
</robot>
